06/04/2018 01:25:01 pm (sqlite3.OperationalError) no such column: user_id [SQL: 'SELECT first_name, last_name FROM users WHERE user_id LIKE 101;'] (Background on this error at: http://sqlalche.me/e/e3q8)
Traceback (most recent call last):
  File "/home/anto/Project/masud_projects/100_days_with_python/Day-12/database_sql/venv/lib/python3.6/site-packages/sqlalchemy/engine/base.py", line 1193, in _execute_context
    context)
  File "/home/anto/Project/masud_projects/100_days_with_python/Day-12/database_sql/venv/lib/python3.6/site-packages/sqlalchemy/engine/default.py", line 508, in do_execute
    cursor.execute(statement, parameters)
sqlite3.OperationalError: no such column: user_id

The above exception was the direct cause of the following exception:

Traceback (most recent call last):
  File "/home/anto/Project/masud_projects/100_days_with_python/Day-12/database_sql/venv/database/mydatabase.py", line 80, in print_all_data
    result = connection.execute(query)
  File "/home/anto/Project/masud_projects/100_days_with_python/Day-12/database_sql/venv/lib/python3.6/site-packages/sqlalchemy/engine/base.py", line 942, in execute
    return self._execute_text(object, multiparams, params)
  File "/home/anto/Project/masud_projects/100_days_with_python/Day-12/database_sql/venv/lib/python3.6/site-packages/sqlalchemy/engine/base.py", line 1104, in _execute_text
    statement, parameters
  File "/home/anto/Project/masud_projects/100_days_with_python/Day-12/database_sql/venv/lib/python3.6/site-packages/sqlalchemy/engine/base.py", line 1200, in _execute_context
    context)
  File "/home/anto/Project/masud_projects/100_days_with_python/Day-12/database_sql/venv/lib/python3.6/site-packages/sqlalchemy/engine/base.py", line 1413, in _handle_dbapi_exception
    exc_info
  File "/home/anto/Project/masud_projects/100_days_with_python/Day-12/database_sql/venv/lib/python3.6/site-packages/sqlalchemy/util/compat.py", line 203, in raise_from_cause
    reraise(type(exception), exception, tb=exc_tb, cause=cause)
  File "/home/anto/Project/masud_projects/100_days_with_python/Day-12/database_sql/venv/lib/python3.6/site-packages/sqlalchemy/util/compat.py", line 186, in reraise
    raise value.with_traceback(tb)
  File "/home/anto/Project/masud_projects/100_days_with_python/Day-12/database_sql/venv/lib/python3.6/site-packages/sqlalchemy/engine/base.py", line 1193, in _execute_context
    context)
  File "/home/anto/Project/masud_projects/100_days_with_python/Day-12/database_sql/venv/lib/python3.6/site-packages/sqlalchemy/engine/default.py", line 508, in do_execute
    cursor.execute(statement, parameters)
sqlalchemy.exc.OperationalError: (sqlite3.OperationalError) no such column: user_id [SQL: 'SELECT first_name, last_name FROM users WHERE user_id LIKE 101;'] (Background on this error at: http://sqlalche.me/e/e3q8)
06/04/2018 01:25:46 pm (sqlite3.OperationalError) no such column: first_name [SQL: 'SELECT first_name, last_name FROM addresses WHERE user_id LIKE 101;'] (Background on this error at: http://sqlalche.me/e/e3q8)
Traceback (most recent call last):
  File "/home/anto/Project/masud_projects/100_days_with_python/Day-12/database_sql/venv/lib/python3.6/site-packages/sqlalchemy/engine/base.py", line 1193, in _execute_context
    context)
  File "/home/anto/Project/masud_projects/100_days_with_python/Day-12/database_sql/venv/lib/python3.6/site-packages/sqlalchemy/engine/default.py", line 508, in do_execute
    cursor.execute(statement, parameters)
sqlite3.OperationalError: no such column: first_name

The above exception was the direct cause of the following exception:

Traceback (most recent call last):
  File "/home/anto/Project/masud_projects/100_days_with_python/Day-12/database_sql/venv/database/mydatabase.py", line 80, in print_all_data
    result = connection.execute(query)
  File "/home/anto/Project/masud_projects/100_days_with_python/Day-12/database_sql/venv/lib/python3.6/site-packages/sqlalchemy/engine/base.py", line 942, in execute
    return self._execute_text(object, multiparams, params)
  File "/home/anto/Project/masud_projects/100_days_with_python/Day-12/database_sql/venv/lib/python3.6/site-packages/sqlalchemy/engine/base.py", line 1104, in _execute_text
    statement, parameters
  File "/home/anto/Project/masud_projects/100_days_with_python/Day-12/database_sql/venv/lib/python3.6/site-packages/sqlalchemy/engine/base.py", line 1200, in _execute_context
    context)
  File "/home/anto/Project/masud_projects/100_days_with_python/Day-12/database_sql/venv/lib/python3.6/site-packages/sqlalchemy/engine/base.py", line 1413, in _handle_dbapi_exception
    exc_info
  File "/home/anto/Project/masud_projects/100_days_with_python/Day-12/database_sql/venv/lib/python3.6/site-packages/sqlalchemy/util/compat.py", line 203, in raise_from_cause
    reraise(type(exception), exception, tb=exc_tb, cause=cause)
  File "/home/anto/Project/masud_projects/100_days_with_python/Day-12/database_sql/venv/lib/python3.6/site-packages/sqlalchemy/util/compat.py", line 186, in reraise
    raise value.with_traceback(tb)
  File "/home/anto/Project/masud_projects/100_days_with_python/Day-12/database_sql/venv/lib/python3.6/site-packages/sqlalchemy/engine/base.py", line 1193, in _execute_context
    context)
  File "/home/anto/Project/masud_projects/100_days_with_python/Day-12/database_sql/venv/lib/python3.6/site-packages/sqlalchemy/engine/default.py", line 508, in do_execute
    cursor.execute(statement, parameters)
sqlalchemy.exc.OperationalError: (sqlite3.OperationalError) no such column: first_name [SQL: 'SELECT first_name, last_name FROM addresses WHERE user_id LIKE 101;'] (Background on this error at: http://sqlalche.me/e/e3q8)
